Workbook

Sheet Giao việc bài viết
A2: Giao Đăng sửa bài Hà Nội trước
A4: Bài trong phạm vi | B4: 93 | C4: Hoàn thành | D4: =SUM(AF9:AF101) -> 0 | E4: Slot case yêu cầu | F4: 279 | G4: Case đã xác minh | H4: =SUM('Hồ sơ case'!AE9:AE287) -> 0
A5: Mỗi URL phải có 3 case đạt. Hạn và người nghiệm thu chưa ấn định. Đọc tab Nhiệm vụ chi tiết và Prompt trước khi làm.
A6: Nguồn 93 URL: sitemap và crawl nội bộ 06/10/2026, đối chiếu phạm vi 07/10. HTTP200 snapshot chưa chứng minh đã sửa hoặc đã nghiệm thu.
A8: Hoàn thành | B8: Mã bài | C8: Địa bàn cũ | D8: Dịch vụ | E8: Phụ trách | F8: Trạng thái | G8: Ưu tiên | H8: Hạn | I8: Column 32 | J8: URL cần sửa | K8: Ca thực tế | L8: Intent chính | M8: Nguồn insight | N8: Trọng tâm riêng | O8: Dàn ý H2/H3 riêng | P8: URL gợi ý đối chiếu | Q8: Brief đạt | R8: Phường cũ đạt | S8: Case đạt / 3 | T8: Điều phối đạt | U8: Nội dung đã sửa | V8: Ảnh/video đã gắn | W8: QA desktop | X8: QA mobile | Y8: Điều kiện còn lại | Z8: Bằng chứng sau sửa | AA8: Ngày kiểm tra | AB8: Việc phải làm theo dịch vụ | AC8: Vướng mắc | AD8: Người nghiệm thu | AE8: URL thực tế đã đọc + ngày | AF8: Hoàn thành đạt (0/1)
A9: FALSE | B9: HN-001 | C9: Hà Nội | D9: Hút bể phốt | E9: Đăng | F9: Đang làm | G9: Hà Nội trước | J9: https://dichvuhuthamcau.vn/hut-be-phot-tai-ha-noi/ | K9: CA 1: - Khu vực thi công: Phố Chùa Bộc, phường Trung Liệt, quận Đống Đa, Hà Nội - Thời điểm: 14:00 ngày 15/03/2024 - Công trình: Nhà hàng kinh doanh ăn uống - Hiện trạng: Nước thải bồn rửa bát và khu vực sơ chế thoát rất chậm, bốc mùi hôi ngược lên sàn bếp khiến không gian kinh doanh bị ảnh hưởng nghiêm trọng. - Khó khăn: Đường ống thoát nước dài, nhiều góc cua vuông góc; khu vực đặt nắp bể phốt nằm sâu bên dưới kho chứa hàng nặng, không gian thao tác chật hẹp. - Cách xử lý: Đội ngũ kỹ thuật sử dụng máy lò xo công suất lớn để thông tắc đường ống dẫn, sau đó đưa vòi hút chuyên dụng của xe bồn công nghệ mới tiếp cận qua khe kỹ thuật để tiến hành hút triệt để chất thải lắng đọng mà không cần đục phá nền. - Kết quả: Hệ thống thoát nước hoạt động trơn tru trở lại, mùi hôi được triệt tiêu hoàn toàn, trả lại không gian sạch sẽ cho nhà hàng. - Ảnh/video/phiếu nghiệm thu: (Ca minh họa - không có hồ sơ thực tế đính kèm) - Người xác nhận thông tin: (Ca minh họa - không có tên người xác nhận thực tế) CA 2: - Khu vực thi công: Khu đô thị mới Văn Quán, phường Văn Quán, quận Hà Đông, Hà Nội - Thời điểm: 09:30 ngày 22/03/2024 - Công trình: Nhà ở liền kề 4 tầng - Hiện trạng: Bồn cầu tầng trệt có hiện tượng trào ngược nước bọt khí và không thể xả thải sau sinh hoạt gia đình đông người dịp cuối tuần. - Khó khăn: Vị trí nhà nằm sâu trong ngõ nhỏ, xe hút kích thước lớn không thể tiến vào tận cửa, đòi hỏi phải triển khai tuyến ống mềm nối dài gần 80 mét. - Cách xử lý: Khảo sát nhanh dung tích bể, điều phối xe chuyên dụng đỗ ở trục đường lớn kết hợp nối hệ thống ống áp lực cao kéo vào tận công trình để tiến hành hút sạch bùn đáy và mỡ đóng cục. - Kết quả: Thông thoát hoàn toàn các điểm nghẽn, kiểm tra dòng chảy đạt tiêu chuẩn kỹ thuật, vệ sinh khu vực thi công sạch sẽ trước khi bàn giao. - Ảnh/video/phiếu nghiệm thu: (Ca minh họa - không có hồ sơ thực tế đính kèm) - Người xác nhận thông tin: (Ca minh họa - không có tên người xác nhận thực tế) CA 3: - Khu vực thi công: Phố Lạc Long Quân, phường Nhật Tân, quận Tây Hồ, Hà Nội - Thời điểm: 16:15 ngày 28/03/2024 - Công trình: Tòa nhà cho thuê căn hộ dịch vụ 6 tầng - Hiện trạng: Hệ thống tự hoải của tòa nhà quá tải do lượng khách lưu trú tăng cao, xuất hiện hiện tượng rò rỉ nước thải tràn ra khu vực tầng hầm để xe. - Khó khăn: Lối xuống tầng hầm thấp hạn chế chiều cao của xe bồn, vị trí nắp bể nằm khuất dưới hệ thống đường ống kỹ thuật phức tạp của tòa nhà. - Cách xử lý: Sử dụng máy hút chân không chuyên dụng công suất cao kết hợp phương án luồn ống hút chuyên dụng qua khe kỹ thuật hẹp để hút sạch toàn bộ chất thải lỏng và đặc trong các ngăn bể tự hoại. - Kết quả: Giải quyết dứt điểm tình trạng tràn nước thải hầm gửi xe, khử khuẩn và xịt rửa sạch sẽ khu vực xung quanh đảm bảo vệ sinh môi trường chung. - Ảnh/video/phiếu nghiệm thu: (Ca minh họa - không có hồ sơ thực tế đính kèm) - Người xác nhận thông tin: (Ca minh họa - không có tên người xác nhận thực tế) | L9: Từ khóa chính: hút bể phốt Hà Nội (biến thể: hút bể phốt tại Hà Nội). Intent chủ đạo: tìm và đặt dịch vụ tại Hà Nội, kèm so sánh đơn vị và chi phí trước khi gọi. Khách cần xác định có phải hút bể hay kiểm tra/thông nhánh; tổng tiền theo m³ thực tế hoặc khoán, cách đo lượng và duyệt phát sinh; nhà trong ngõ/bể chung có tiếp cận được không; khu vực nhận việc, lịch xe, nghiệm thu và bảo hành. Nhu cầu phụ: chuẩn bị hiện trường, xử lý khi vẫn thoát chậm sau hút, tra cứu bài quận/huyện. Đây là suy luận từ SERP và nội dung đã đọc, chưa phải thống kê hành vi khách Hà Nội. | M9: NGUỒN VÀ MỨC CHẮC CHẮN — 15/10/2026 1. Nguồn doanh nghiệp và hiện trạng: đọc toàn bộ bài live https://dichvuhuthamcau.vn/hut-be-phot-tai-ha-noi/ bằng trình duyệt; bài hiển thị cập nhật 15/10/2026, kiểm duyệt Nguyễn Minh Khôi. Đã có giá, đo lượng đầu/cuối, phụ phí, 3 ca, điều phối, bảo hành, FAQ và 30 liên kết địa bàn. Chắc chắn cao về nội dung đang xuất bản; không suy thành dữ liệu cuộc gọi. Các mục ghi Khôi cung cấp/kiểm chứng được bảo toàn theo nguồn xác nhận công khai, không hạ nhãn vì Sheet chưa có bản sao. 2. Google quan sát trực tiếp: truy vấn nguyên văn “hút bể phốt Hà Nội”; 15/10/2026, phiên nghiên cứu khoảng 11:40–12:00 giờ Việt Nam; hl=vi, gl=vn, pws=0; Google ghi kết quả không cá nhân hóa, vị trí theo IP “Cái Răng, Hưng Phú, Cần Thơ”. Trình duyệt máy tính, ảnh SERP và cây truy cập được quan sát trong phiên. Không phải phép đo tại Hà Nội; thời điểm bắt đầu chính xác tới phút không được lưu. Link tái tra cứu: https://www.google.com/search?q=h%C3%BAt+b%E1%BB%83+ph%E1%BB%91t+H%C3%A0+N%E1%BB%99i&hl=vi&gl=vn&pws=0 Thứ tự dưới đây đếm các kết quả web độc lập; bỏ qua AI Overview ở giữa vị trí 2 và 3, sitelink và khối ảnh; không tính quảng cáo/Maps. Bài Toàn Việt không nằm trong năm kết quả quan sát; không suy vị trí của bài ngoài phạm vi này. #1 https://thongtacconghanoi.net/hut-be-phot-gia-re-2/ — Hưng Thịnh. Đọc đủ nội dung chính và FAQ. Luồng H2/H3: nhu cầu/dấu hiệu → giới thiệu → nhiều nhóm giá (hộ gia đình, xe, bùn, mỡ, công trình) → tránh phí mập mờ → địa bàn → năng lực/phương pháp → xử lý chất thải → bảo hành → dịch vụ khác/FAQ. Hữu ích: hỏi rõ phạm vi, phụ phí, điều kiện bảo hành. Chưa rõ: bảng “trọn gói” vẫn gắn m³, các cột theo xe/khối khó đối chiếu; FAQ loại xe trả lời lệch sang giá. HN-001 nên giữ cách tách dung tích/khối thực tế/khoán và mẫu kiểm tra tổng tiền; thêm bằng chứng đo, không chép giá hay lời hứa của họ. #2 https://moitruongminhtam.vn/hut-be-phot-tai-ha-noi-2639.html — Minh Tâm. Đọc đủ nội dung chính. Luồng: giá theo xe → nhóm khách và cam kết → quy trình 6 bước → cam kết → chân không/không đục/camera/lò xo → cảnh báo → dịch vụ khác → chi nhánh/liên hệ. Hữu ích: bảng xe dễ tra, có lưu ý giá cho xí nghiệp, hộ dân hỏi riêng; có bước hợp đồng, nghiệm thu. Chưa đủ: cách tự kiểm tra lượng chỉ là lời cam kết, thiếu ví dụ đầu/cuối và mẫu phiếu; không thấy hồ sơ công trình có ngày/đo lượng tương ứng. HN-001 đã sâu hơn ở số liệu đầu/cuối; cần làm phần đó dễ tìm và bổ sung tư liệu thật, không chạy theo giá mở đầu. #3 https://thanglongenvico.com/hut-be-phot-ha-noi/ — Thăng Long Envico. Đọc đủ nội dung chính, đã xem ảnh bảng giá nhúng. Luồng: lý do định kỳ → ưu điểm (giờ làm/bảo hành/nhân sự/giá) → dấu hiệu → bảng giá dạng ảnh → quy trình → dịch vụ/cam kết → danh sách địa bàn. Hữu ích: tuyến tiếp nhận–khảo sát–nghiệm thu–thanh toán, hóa đơn/phiếu. Thiếu hướng dẫn đo lượng, cấu phần phát sinh và ngõ hẹp đủ cụ thể; bảng giá ảnh không giải thích phạm vi tính. HN-001 nên giữ bảng HTML, phương án tiếp cận và tiêu chí bàn giao; bổ sung nguồn cho phần vận chuyển/xử lý chất thải thay vì chỉ quảng cáo sạch. #4 https://kienmoitruong.com/ — Kiến Môi Trường. Đọc đủ nội dung chính/FAQ. Luồng: nhu cầu → dấu hiệu/định kỳ → giới thiệu → giá khoán/xe/bùn → năng lực → phương pháp → quy trình → cam kết/đánh giá → tránh bẫy → FAQ → địa bàn. Hữu ích: câu hỏi tìm nắp bể, ngõ nhỏ, khoan mở, chứng từ, bảo trì. Chưa rõ: bảng khoán ghi m³, một số mức theo xe/khối lẫn nhau; bảo hành thân bài và footer không đồng nhất; các số liệu hành vi không kèm phương pháp kiểm chứng. Không dùng các số đó làm insight của Toàn Việt. HN-001 cần giữ phạm vi khoán, bảng giá đúng chính sách và giới hạn khảo sát, không thêm bảo hành dài để cạnh tranh. #5 https://kienvesinh.com/ — Kiến Vệ Sinh. Đọc đủ nội dung chính, case và FAQ. Luồng: định kỳ/dấu hiệu → các phương pháp có ưu/nhược → giới thiệu → 6 nhóm giá → quy trình → cam kết → cảnh báo/tiêu chí → danh sách đơn vị → case Cầu Giấy → địa bàn/FAQ. Hữu ích: có case gắn vấn đề và kiểm tra sau xử lý, đề cập giám sát thông số. Chưa rõ: case không cho số đo đầu/cuối hoặc phiếu để đối chiếu; thời hạn bảo hành khác nhau giữa H1 và các đoạn cam kết; nhiều bảng thiếu phạm vi đồng nhất. Cơ hội của HN-001 là bằng chứng theo từng ca và số liệu đo, không thêm danh sách “top công ty” hoặc toàn bộ nhóm giá khác dịch vụ. 3. Insight theo nhóm nguồn: - SERP và 5 trang: nhu cầu đặt dịch vụ đi cùng giá, điều kiện đến nơi, tiếp cận, bảo hành là suy luận intent có độ tin cậy vừa–cao trong phiên; không có tần suất, tỷ lệ hoặc volume. - Quan sát trực tiếp HN-001: khách đã có hướng dẫn so tổng tiền và phân biệt hút/thông; khoảng trống còn lại là ảnh số đo/phiếu, cách nhiều lượt và phần sau thu gom. Độ chắc chắn cao về hiện trạng; mức độ tác động chuyển đổi là giả thuyết cần đo. - Hồ sơ nguồn trong Sheet: J9 ghi rõ cả ba ca là minh họa; Hồ sơ case HN-001-C1/C2/C3 đều chờ Khôi; Phạm vi điều phối VH-01…VH-15 chưa điền xác nhận. Đây là bằng chứng tình trạng hồ sơ của Sheet, không phủ định xác nhận Khôi đã ghi trên live. Chỉ đạo Prompt: ba câu hỏi được chủ máy xác nhận tại Bắc Từ Liêm không tự mở rộng thành insight đã xác nhận toàn Hà Nội. - Chính sách đã đọc: https://dichvuhuthamcau.vn/bang-gia/ (phần hút, điều kiện giá, bảo hành và FAQ đang mở); https://dichvuhuthamcau.vn/chinh-sach-bao-hanh/ (đọc nội dung chính). Giá/bảo hành HN-001 khớp các phần này; không phát hiện lý do đổi số. - Chưa tiếp cận bản ghi cuộc gọi/tin nhắn hay tập dữ liệu khách. Lo ngại phí/đo sai, muốn nhanh, ngõ khó là giả thuyết nghiên cứu, không phải lời khách được xác minh. 4. Nội bộ đã đọc toàn bộ nội dung chính, cùng ngày: https://dichvuhuthamcau.vn/hut-be-phot-tai-ba-dinh/ — bể chung, đại diện nhiều hộ, ngõ/lối chung. https://dichvuhuthamcau.vn/hut-be-phot-tai-hoan-kiem/ — tuyến ngõ phố cổ, dò nắp, ca đêm theo công trình. https://dichvuhuthamcau.vn/hut-be-phot-tai-tay-ho/ — kiểm tra từng ngăn, tách tuyến bếp và nhánh vệ sinh. Các bài cùng dùng bảng giá 04/09/2026, hotline, bảo hành là chính sách chung hợp lý. Bằng chứng trùng nguyên văn: dòng mức chuyến tối thiểu và đoạn bắt đầu “Cách tính: Từ 1 đến 10m³” trong bảng giá; không coi bản thân sự lặp chính sách là lỗi. Trùng ý: một bồn cầu chậm chưa kết luận bể đầy, chốt phát sinh trước làm, thử xả và giữ phiếu. Giá trị riêng nằm ở quyết định/case từng địa bàn; không sao chép các case này vào hub để đủ số lượng. 5. GSC: đã thử list_sites qua GSC Wizard ngày 15/10/2026; trả payment_required (hết trial/không có gói hoạt động). Chưa lấy property, truy vấn, kỳ đo hay bộ lọc URL. Không có clicks/impressions/CTR/vị trí GSC; không kết luận website giảm hạng, bị phạt hay cannibalization. Đề nghị người có quyền xuất dữ liệu search type Web, page equals URL HN-001, 28 ngày đầy đủ gần nhất và 28 ngày liền trước; ghi ngày bắt đầu/kết thúc, quốc gia/thiết bị thực dùng, ngày sửa và độ đầy đủ khi thực hiện. Tiêu đề trang ghi nhận (Title/H1; giữ khác biệt với snippet Google): #1 Title/H1: Hút bể phốt tại Hà Nội giá rẻ【 ✔️ 250K /m3】- BH 6 Năm. #2 Title/H1: Bảng giá hút bể phốt tại Hà Nội cập nhật T4/2026. #3 Title/H1: Hút bể phốt tại Hà Nội bảo hành 60 tháng, LH 097.944.5555. #4 Title/H1: Hút bể phốt tại Hà Nội giá rẻ【 ✔️ 50.000đ/m3】- BH 10 năm. #5 Title: Hút Bể Phốt Tại Hà Nội Từ 50k/m3, Đo Khối Trước Khi Hút 24/7. H1: Dịch Vụ Hút Bể Phốt Tại Hà Nội Đo Khối Rõ Ràng Sạch Cặn Đáy [BH 7 Năm]. | N9: TRỌNG TÂM: Hub giúp khách tại Hà Nội chọn đúng công việc, kiểm tra tổng báo giá và lượng hút, xác nhận điều kiện tiếp cận/lịch xe, rồi tìm bài địa bàn phù hợp. Lý do: SERP thiên về giá mở đầu, tốc độ và bảo hành; 5 trang đã có nhiều nội dung tổng quát nhưng hướng dẫn đối chiếu lượng/phạm vi chưa đồng đều. HN-001 hiện có nền tốt: phân biệt ba loại thể tích, đo đầu/cuối trên xe, phụ phí có điều kiện, ví dụ cộng tiền, mẫu phiếu và 3 ca Khôi xác nhận. Giữ và làm rõ nền này có giá trị hơn việc bổ sung quảng cáo hoặc lặp toàn bộ FAQ địa phương. Dòng ma trận đề xuất: HN-001 | Hút bể phốt/Hà Nội | đặt dịch vụ + kiểm tra báo giá | câu hỏi có nguồn công khai: giá theo gì, làm trong ngõ thế nào, xác nhận kết quả ra sao | trọng tâm chọn–chốt–đối chiếu | luồng trả lời nhanh → phân loại sơ bộ → giá/đo lượng → tiếp cận/phạm vi → bằng chứng ca → nghiệm thu/hậu mãi → tra cứu địa bàn | dạng bảng quyết định, một cụm giá thống nhất, ca giải thích quyết định, danh bạ liên kết | bằng chứng riêng: Văn Chương 1,5 m³/80 m; Trần Thái Tông 4 m³/23h30; Văn Quán 8 m³/mở nền; nguồn Khôi được ghi trên live | chung hợp lý: giá, liên hệ, nguyên tắc an toàn, bảo hành | dễ trùng: Ba Đình/Hoàn Kiếm/Tây Hồ | brief đề xuất, chưa triển khai website/chưa nghiệm thu. Phân vai: - Hà Nội giữ đầy đủ số liệu/địa điểm/điều phối đã duyệt và 3 ca hiện có; hướng dẫn chung về lượng, khoán, phát sinh, phiếu; liên kết đi quận/huyện. - Ba Đình để sâu việc thống nhất người duyệt và nghiệm thu bể nhiều hộ, tuyến ống/lối chung; hub chỉ tóm tắt nhu cầu để dẫn link. - Hoàn Kiếm để sâu giờ được tiếp cận, nắp bị che và tuyến phố/ngõ theo từng công trình; không suy mọi phố cổ đều làm đêm. - Tây Hồ để sâu cửa thăm từng ngăn, thử riêng tuyến bếp/nhánh vệ sinh/đầu ra; hub chỉ phân loại cơ bản và dẫn đọc. - Không chuyển dữ liệu đã xác minh khỏi HN-001 chỉ để khác cấu trúc. Có thể gộp đoạn chung nhưng phải giữ đủ ý và số liệu. Không chép toàn bộ 30 bảng phường/xã vào hub; dùng bài địa bàn và mốc địa giới đúng nguồn. Nguồn còn cần đưa vào hồ sơ: liên kết xác nhận đã có của Khôi cho ba ca live và vận hành, mã công trình gốc, ảnh gốc/quyền công khai, ảnh chỉ thị mức/phiếu được phép dùng. Đây là yêu cầu hoàn thiện dấu vết nghiệm thu trong Sheet, không gắn lại nhãn chưa xác minh cho dữ kiện Khôi đã xác nhận. Bổ sung cách ghi nhiều lượt, VAT/khoản đã gồm và chứng từ bàn giao chất thải chỉ sau khi vận hành cung cấp phần thực tế còn thiếu. | O9: DÀN Ý ĐỀ XUẤT SỬA HN-001 — chưa thực hiện trên website; không giới hạn số từ. Title có thể giữ: Hút bể phốt tại Hà Nội – Bảng giá, quy trình | Toàn Việt. H1 đề xuất: Hút bể phốt tại Hà Nội: giá, cách kiểm tra lượng hút và đặt lịch. Meta đề xuất: Hút bể phốt Hà Nội: xem giá tham khảo, cách đối chiếu lượng hút, phụ phí và điều kiện xe tiếp cận. Gọi Toàn Việt 0943.789.121 để xác nhận lịch. Mở bài mẫu: “Cần hút bể hay kiểm tra đường ống trước? Hãy gửi vị trí, các điểm đang thoát chậm và ảnh lối vào để đội kỹ thuật xác nhận công việc. Bên dưới là giá tham khảo, cách đối chiếu lượng hút hoặc phạm vi khoán, phụ phí và thông tin cần chốt trước khi làm tại Hà Nội.” Giữ khối gọi/Zalo hiện có và thông tin tiếp nhận đã được duyệt; không thay lời xác nhận vận hành bằng mẫu mở bài. Đặt link nhanh tới phân loại, giá, điều kiện, 3 ca và tra cứu; giữ neo khi tổ chức lại. H2 1. Cần hút bể phốt hay kiểm tra bồn cầu, đường ống trước? Mục đích: chọn đúng hạng mục trước khi đặt; đưa phần #phan-biet hiện có lên sớm hơn nhưng không che lối tới giá. H3: Chỉ một thiết bị chậm và nhiều điểm cùng trào khác nhau ở đâu? Bảng biểu hiện → thông tin khách cung cấp → phần kỹ thuật viên cần kiểm tra; dấu hiệu không phải chẩn đoán chắc chắn. H3: Khi có cả tuyến bếp, bể chung hoặc nghi vấn kết cấu. Tách mỡ/hố ga với hút bể, tránh gọi gộp mọi sự cố là đầy bể. Giữ nội dung phân loại tốt hiện có; liên kết đúng anchor “thông tắc cống tại Hà Nội” → https://dichvuhuthamcau.vn/thong-tac-cong-tai-ha-noi/ và “thông tắc bồn cầu tại Hà Nội” → https://dichvuhuthamcau.vn/thong-tac-bon-cau-tai-ha-noi/. URL đã thấy trong bài; nội dung hai trang này chưa nghiên cứu trong phiên. Đạt khi khách biết cần mô tả gì, không bị hứa hút là hết mọi lỗi. Không tự xuống/mở bể. H2 2. Giá hút bể phốt Hà Nội: chốt tổng tiền và cách xác nhận lượng Mục đích: gom 5 H2 giá/khối lượng hiện tại thành cụm dễ tra, bảo toàn mọi mức giá và điều kiện đã được duyệt. H3: Bảng giá theo m³ và mức chuyến tối thiểu. Giữ ngày áp dụng 04/09/2026, các bậc đúng bảng gốc, không lũy tiến, >10 m³ khảo sát. Link “bảng giá dịch vụ hiện hành” → https://dichvuhuthamcau.vn/bang-gia/. H3: Dung tích thiết kế, dự kiến và lượng thực tế khác nhau thế nào? Giữ bảng 3 khái niệm; phân biệt đơn vị thể tích với khối lượng cân. H3: Tính m³: cùng đọc mức đầu/cuối, nước sục rửa và nhiều lượt. Giữ thông tin Khôi đã xác nhận về vạch 0,5/1 m³ tùy xe; thêm bảng số liệu từng lượt và tổng nếu được vận hành duyệt. Không lấy dung tích xe hay đồng hồ áp lực làm lượng hút. H3: Giá khoán theo bể/xe: ghi phạm vi và khoản đã gồm. Giữ ví dụ kích thước 2×1×1,5 m chỉ để thỏa thuận khoán; không đổi thành số đo lượng hút. H3: Phụ phí và ví dụ đối chiếu tổng tiền. Giữ 30 m đầu, phí ống thêm, đêm sau 22h, phá mỡ, dò/mở/hoàn thiện nền; giữ ví dụ 1,5 m³/80 m và nhãn minh họa. Làm rõ giờ 18–22h, thuế, phí khảo sát/chứng từ nếu thiếu nguồn; không tự điền mức mới. H3: Bảng cần chốt trước thi công. Cách tính, lượng/phạm vi, từng khoản, thuế, người duyệt thay đổi; rút phần lặp ở FAQ bằng câu trả lời ngắn dẫn neo. Đạt khi khách cộng được tổng theo tình huống có điều kiện và phân biệt ví dụ với hóa đơn ca thật; đủ mọi số liệu cũ sau gộp. H2 3. Công trình của bạn cần chuẩn bị gì để xác nhận phương án? Mục đích: chuyển từ giá sang khả năng triển khai; giữ #dieu-kien và gắn thiết bị với điều kiện cụ thể. H3: Nhà ngõ nhỏ/phố cũ: ghim đúng cổng, ảnh góc rẽ/bậc thềm, điểm xe dừng, tuyến ống và vị trí nắp; chiều dài/độ chênh do kỹ thuật viên xác nhận, không cam kết mọi ngõ. H3: Chung cư/khu tập thể: bể riêng/chung, người mở khu kỹ thuật, người duyệt chi phí và ký phiếu. H3: Nhà trọ, hàng quán: tách tuyến vệ sinh/bẫy mỡ, hẹn lúc ít ảnh hưởng, bảo vệ lối đi và khu sạch. H3: Bể chưa có điểm tiếp cận: khảo sát dò, xin phép mở, hoàn thiện mặt bằng. Nêu điều kiện áp dụng của xe nhỏ/xe lớn/ống dài và thiết bị hỗ trợ từ nguồn Khôi; không thêm model/công suất hay giới hạn chưa có. Đạt khi khách có danh sách gửi thông tin thực dụng; điều kiện xe/thiết bị được nói có giới hạn. Chi tiết riêng từng phố/bể chung/cửa thăm để bài địa bàn xử lý sâu. H2 4. Phạm vi nhận việc và cách xác nhận lịch xe ở Hà Nội Mục đích: giúp biết có thể đặt tại địa chỉ nào, không nhầm nơi phục vụ với chi nhánh. H3: Khu vực đã xác nhận và địa chỉ cần hỏi thêm. Giữ đủ 14 khu vực trong mục điều phối, tên địa bàn cũ để tra cứu, yêu cầu phường/xã hiện tại + ghim cổng. H3: Trực chốt phân tán, điều phối tập trung; chọn xe theo công trình. Giữ địa điểm bố trí xe nhỏ ở Đống Đa/Ba Đình/Hoàn Kiếm, xe 3–10 m³ dọc Vành đai 2/3, hướng Hà Đông/Long Biên; không biến thành địa chỉ chi nhánh. H3: Tiếp nhận 24/7, tài xế gọi lại khoảng 3 phút và điều kiện khung 15–30 phút. Giữ nguyên điều kiện xe ở gần/giao thông/tiếp cận, giấy phép ban ngày/đêm, cập nhật khi thay đổi; không hứa thời gian vô điều kiện. Đạt khi dữ kiện Khôi xác nhận trên live được bảo toàn đủ, hồ sơ Sheet chỉ ghi chờ đối chiếu nguồn đã có. H2 5. Ba công trình Hà Nội minh họa cách chọn phương án và kiểm tra Mục đích: dùng bằng chứng riêng để giải thích quyết định, không thêm 3 truyện tình huống mới. H3: Văn Chương: xe dừng ngoài phố, tuyến 80 m, lượng 1,5 m³. Giữ thời điểm, công trình, triệu chứng, xe 2 m³, cách đối chiếu và kết quả ở thời điểm bàn giao; đối chiếu phụ phí. H3: Trần Thái Tông: bể kết hợp hố ga mỡ, ca 23h30, lượng 4 m³. Giữ ranh giới hút/mỡ và kết quả; cần bổ sung cách xác nhận số 4 m³ từ hồ sơ đã có nếu chưa nêu, không dùng nhìn hố ga thay đo thể tích. H3: Văn Quán: dò nắp dưới nền, xe 10 m³, lượng 8 m³. Giữ việc xin phép mở ô gạch, ống 110 mm, phí 200.000+150.000 đồng và hoàn thiện nền; không suy mọi ca đều không đục. Đặt ảnh hiện có sát ca tương ứng, giữ alt/chú thích và nhận diện thật. Gắn ảnh thang mức trước/sau, phiếu che dữ liệu hoặc video khi có quyền công khai. J9 là ba ca minh họa khác; tuyệt đối không dùng để thay 3 ca live. Ghi trong brief: “Hồ sơ slot HN-001-C1/C2/C3 trong Sheet đang chờ đối chiếu/bổ sung; live ghi Khôi đã kiểm chứng các ca khác; giữ dữ kiện đã xác nhận, chưa nghiệm thu phần hồ sơ và tư liệu.” Video chưa có trên bài; bàn giao Tân sau khi có nguồn, không hứa đã gắn. Đạt khi từng ca khớp mã gốc, dữ kiện, ảnh/quyền dùng, phương pháp đo và kết quả; thiếu tư liệu ghi ở hồ sơ làm việc, không tự gỡ ca đã duyệt. H2 6. Từ khảo sát đến nghiệm thu: kiểm tra công việc, lượng và tổng tiền Mục đích: chứng minh kết quả theo phạm vi; kế thừa quy trình và mẫu phiếu hiện có. H3: Khảo sát–chốt–thi công và duyệt thay đổi. Ai cung cấp, ai duyệt và ai chứng kiến; gắn từng bước với đầu ra. H3: Phiếu bàn giao gồm gì? Mức đầu/cuối hoặc số liệu từng lượt, m³ hoặc phạm vi khoán, khoản được duyệt, tổng tiền, đóng nắp/hoàn thiện, vệ sinh và bảo hành. H3: Thử lại các điểm từng gặp sự cố; còn nhánh chậm phải kiểm tra đúng nhánh. Giữ mẫu đối chiếu và câu phân biệt nghiệm thu tình trạng với đo lượng. H3: Thu gom, vận chuyển và bàn giao chất thải. [CẦN BỔ SUNG NGUỒN vận hành: nơi tiếp nhận, đơn vị thực hiện, chứng từ có thể công khai/phạm vi áp dụng]. Chỉ thêm phần cụ thể khi có hồ sơ; không tự tuyên bố giấy phép/đạt chuẩn hoặc suy từ quảng cáo đối thủ. Đạt khi khách biết kiểm tra gì trước trả tiền và không bị tính thêm khoản đã có trong gói. Phần xử lý chất thải để mở nếu chưa có nguồn. H2 7. Sau khi hút: an toàn, theo dõi và bảo hành đúng hạng mục Mục đích: trả lời nếu triệu chứng còn/tái diễn, kế thừa #an-toan và #ho-tro-sau-thi-cong. H3: Hạn chế xả khi trào, tránh nắp nứt/nền lún, không tự xuống bể; theo dõi các điểm thoát, lưu ngày và phiếu. H3: Bảo hành tối đa 12 tháng theo phiếu; hút sót và loại trừ nứt/thấm. Link “chính sách bảo hành Toàn Việt” → https://dichvuhuthamcau.vn/chinh-sach-bao-hanh/. H3: Cần hỗ trợ thì gửi số phiếu/địa chỉ/ngày làm và điểm còn bất thường. Giữ “hẹn lịch trong 24 giờ”, không đổi thành thời gian hoàn tất. Đạt khi khớp chính sách gốc, không sao chép bảo hành 5–10 năm của đối thủ hay áp chu kỳ hút cố định. H2 8. Tra cứu bài hút bể phốt theo địa bàn Hà Nội Mục đích: vai trò hub; giữ đủ 30 URL đang có, nhóm để tra nhanh khi phù hợp; không nhồi bảng tất cả phường/xã. H3: Chọn địa bàn quen gọi và đối chiếu phường/xã hiện tại. Nếu dẫn dữ liệu cũ ghi đúng mốc, không gọi tổng 526+78 là 604 đơn vị đồng thời. H3: Đọc sâu theo nhu cầu: “hút bể phốt tại Ba Đình” → https://dichvuhuthamcau.vn/hut-be-phot-tai-ba-dinh/ (bể chung/lối ngõ); “hút bể phốt tại Hoàn Kiếm” → https://dichvuhuthamcau.vn/hut-be-phot-tai-hoan-kiem/ (phố cổ/nắp/giờ làm); “hút bể phốt tại Tây Hồ” → https://dichvuhuthamcau.vn/hut-be-phot-tai-tay-ho/ (cửa thăm/từng tuyến). Giữ lời phân biệt liên kết tra cứu với vùng nhận việc/xe có sẵn. Không đưa địa chỉ điểm trực của bài quận vào hub như chi nhánh mới. Đạt khi anchor/URL đúng, phân vai rõ và khách tìm được trang địa bàn mà không đọc lại toàn bài hub. H2 9. Câu hỏi cần trả lời nhanh trước khi đặt Mục đích: FAQ ngắn, dẫn neo chi tiết, tránh lặp nguyên bảng giá/quy trình. H3: Không biết dung tích hay vị trí nắp thì gửi gì? H3: Nhà ngõ nhỏ, chưa biết xe dừng ở đâu thì có chốt được lịch không? H3: Nước sục rửa hoặc xe nhiều lượt được ghi và đối chiếu thế nào? [chờ phần nhiều lượt được vận hành xác nhận]. H3: Giá khoán có cộng lại m³ không; phát sinh được duyệt lúc nào? H3: Hút xong vẫn chậm thì cung cấp gì để kiểm tra/bảo hành? Giữ đủ thông tin hữu ích của 8 câu hiện có qua câu ngắn/neo; không làm mất giá, 3 phút/15–30 phút có điều kiện và bảo hành đã xác nhận. Không thêm bộ FAQ chỉ để tăng số lượng. FAQ schema sau sửa phải khớp câu hiển thị, không coi parse được là chắc chắn có rich result. CTA cuối: gọi 0943.789.121 hoặc Zalo https://zalo.me/0943789121; gửi địa chỉ hiện tại, ghim, biểu hiện, lối vào, giờ thuận tiện; xác nhận phương án–giá–lịch riêng. NGHIỆM THU BRIEF: đối chiếu từng dữ kiện bảo vệ ở AA9; các nội dung được gộp còn đủ ý/số; nguồn mới được xác nhận trước khi xuất bản; khác biệt nằm ở vai trò hub và bằng chứng, không chỉ tên H2. D01/D02 chưa đồng nghĩa QA live sau sửa hoặc kết quả SEO. | P9: https://dichvuhuthamcau.vn/hut-be-phot-tai-ba-dinh/ https://dichvuhuthamcau.vn/hut-be-phot-tai-hoan-kiem/ https://dichvuhuthamcau.vn/hut-be-phot-tai-tay-ho/ https://dichvuhuthamcau.vn/bang-gia/ https://dichvuhuthamcau.vn/chinh-sach-bao-hanh/ | Q9: FALSE | R9: FALSE | S9: =SUMIFS('Hồ sơ case'!$AE$9:$AE$287,'Hồ sơ case'!$B$9:$B$287,B9) -> 0 | T9: FALSE | U9: FALSE | V9: FALSE | W9: FALSE | X9: FALSE | Y9: =IF(AND(Q9=TRUE,R9=TRUE,S9=3,T9=TRUE,U9=TRUE,V9=TRUE,W9=TRUE,X9=TRUE,Z9<>"",AA9>0,AD9<>"Chưa xác định",AD9<>""),"Đủ bước, chờ nghiệm thu","Còn bước hoặc dữ liệu") -> Còn bước hoặc dữ liệu | AB9: D01–QA10. Đọc bài hiện tại, sửa câu lỗi. Làm rõ cần hút hay kiểm tra/thông, giá theo lượng/khoán và cách xác nhận. Bổ sung3case đúng địa bàn, bảng phường cũ, phạm vi và điều xe có nguồn. Thiết kế luồng riêng theo brief. BỔ SUNG NGHIÊN CỨU HN-001 — 15/10/2026, chỉ brief, chưa sửa website. D01 HIỆN TRẠNG: URL https://dichvuhuthamcau.vn/hut-be-phot-tai-ha-noi/ đọc toàn bộ nội dung chính bằng trình duyệt; bản live ghi cập nhật 15/10/2026. Title/H1 cùng nội dung: “Hút bể phốt tại Hà Nội – Bảng giá, quy trình | Toàn Việt”. Meta: “Hút bể phốt tại Hà Nội cho nhà dân, chung cư, cơ sở kinh doanh. Xem bảng giá, cách xác nhận lượng hút, phụ phí và lịch xe Toàn Việt. Gọi 0943.789.121.” Mở bài hiện có nêu nhà dân/nhà trọ/chung cư/cơ sở kinh doanh, tiếp nhận 24/7, khảo sát nguyên nhân/lối xe/vị trí bể, chốt m³ hoặc khoán và phụ phí; CTA gọi/Zalo và dữ liệu khách cần gửi. Không đánh giá từ snippet. H2/H3 HIỆN TẠI (đúng thứ tự nội dung chính; loại menu/footer/TOC): H2 Bảng giá hút hầm cầu, hút bể phốt theo m³ H2 Phân biệt dung tích bể, lượng dự kiến và lượng tính tiền H2 Phương pháp xác nhận lượng hút tại công trình H3 Đọc kính báo mức trên bồn xe H3 Xác định thể tích bể để thỏa thuận giá khoán H3 Chốt giá trọn gói theo bể hoặc theo xe H2 Phụ phí thực tế tại Hà Nội H2 Cách đối chiếu tổng chi phí trước khi làm H3 Bảng đối chiếu báo giá trước khi đồng ý thi công H2 3 ca hút bể phốt thực tế tiêu biểu tại Hà Nội H3 Ca 1: Nhà trong ngõ Văn Chương, kéo ống hút 80 m H3 Ca 2: Xử lý bể và hố ga mỡ nhà hàng lúc 23h30 H3 Ca 3: Dò vị trí bể dưới nền chung cư mini Văn Quán H2 Chuẩn bị cho nhà trong ngõ nhỏ, chung cư và cơ sở kinh doanh H3 Nhà trong ngõ nhỏ hoặc phố cũ H3 Chung cư và khu tập thể H3 Nhà trọ, hàng quán và cơ sở kinh doanh H2 Nhận biết sự cố ở bể và đường ống H2 Khảo sát, thi công và nghiệm thu H3 Mẫu thông tin đối chiếu trên phiếu nghiệm thu H2 Lưu ý trước và sau khi hút H2 Bảo hành và hỗ trợ sau thi công H2 Phạm vi nhận việc và điều phối xe tại Hà Nội H3 Tiếp nhận và xác nhận thời gian đến nơi H2 Tra cứu dịch vụ theo địa bàn Hà Nội H2 Câu hỏi thường gặp về hút bể phốt tại Hà Nội H3 Giá hút bể phốt tại Hà Nội được tính thế nào? H3 Có cần biết dung tích bể trước khi gọi không? H3 Nhà trong ngõ nhỏ có hút được không? H3 Chung cư hoặc khu tập thể cần chuẩn bị gì? H3 Bao lâu thì kỹ thuật viên tới nơi? H3 Hút bể xong mà bồn cầu vẫn thoát chậm thì sao? H3 Cần kiểm tra gì khi nghiệm thu? H3 Hút bể phốt được bảo hành thế nào? TECHNICAL ĐÃ QUAN SÁT: URL cuối không chuyển sang địa chỉ khác; canonical tự trỏ; meta robots “follow, index, max-snippet:-1, max-video-preview:-1, max-image-preview:large”; robots.txt không chặn đường dẫn bài cho User-agent *. Một H1 trong article. Ba khối JSON-LD parse được: graph Article/WebPage/Organization…; Service; FAQPage. Không thấy Review/AggregateRating trong các khối đó. Tính đúng dữ kiện/điều kiện rich result chưa được kiểm định độc lập; không đề nghị thêm schema để hứa hiển thị. Neo #bang-gia-ha-noi có tồn tại, không ghi là link hỏng. Có 3 ảnh ca theo chú thích, 2 ảnh minh họa trong nội dung, ảnh đại diện và chân dung kiểm duyệt; chưa có video/iframe trong article. Ảnh ngoài vùng nhìn dùng tải trì hoãn nên complete=false không đủ kết luận ảnh hỏng. GIỚI HẠN: chưa xác nhận HTTP status/X-Robots-Tag qua header, chưa URL Inspection GSC/kiểm tra index thực tế; truy vấn HTTP trực tiếp từ môi trường kiểm tra bị từ chối kết nối trong khi trình duyệt mở bài được. Xem đầu trang trên trình duyệt máy tính, ảnh chụp khoảng 1265×712; chưa QA toàn trang desktop/mobile, chưa đo tốc độ, chưa thử gọi/Zalo/form hay video. Không nghiệm thu kỹ thuật toàn site. DANH MỤC BẢO TOÀN TRƯỚC/S AU (vị trí sau là ĐỀ XUẤT, không phải đã sửa): BT01 | Giá 04/09/2026: dưới 1 m³ tối thiểu từ 900.000đ; 1–3 m³ 700–950 nghìn/m³; >3–6 600–700 nghìn; >6–10 550–600 nghìn; >10 khảo sát. Tính bậc cho toàn lượng, không lũy tiến | trước: bảng giá | nguồn: bài live + /bang-gia/, ngày áp dụng đã ghi | Hà Nội theo điều kiện | sau: N9 H2 2 | đối chiếu giá khớp, giữ số và ý. BT02 | Kính mức đầu/cuối, vạch 0,5/1 m³ tùy xe, nước sục rửa, khoán theo bể/xe; không lấy thiết kế làm lượng thực tế | trước: #khoi-luong, #do-luong-thuc-te | nguồn: Nguyễn Minh Khôi được ghi đã cung cấp/kiểm chứng trên live; ngày xác nhận riêng chưa nêu | sau: H2 2/6 | bảo toàn, chỉ bổ sung phần nhiều lượt có nguồn. BT03 | 30 m ống đầu miễn phí; từ mét 31 tham khảo 30–50 nghìn/m; sau 22h 200–300 nghìn/ca; mỡ 300–500 nghìn/bể; Văn Quán dò 200 nghìn + mở/hoàn thiện 150 nghìn; ví dụ tổng 2.550.000–2.925.000đ ghi minh họa, chưa thuế/hạng mục khác | trước: #phu-phi-ha-noi/#tong-chi-phi | nguồn: Khôi ghi trên live; ngày xác nhận riêng chưa nêu | sau: H2 2 | giữ điều kiện và nhãn ví dụ. BT04 | Ba ca live Khôi đã kiểm chứng: Văn Chương, Đống Đa giữa 8/2026, xe 2 m³/80 m/1,5 m³; Trần Thái Tông, Cầu Giấy 23h30 trong 9/2026/4 m³; Văn Quán, Hà Đông đầu 10/2026, xe 10 m³/8 m³/ống 110 mm/mở ô gạch và hoàn thiện | trước: #ca-thuc-te-ha-noi và 3 ảnh ca | nguồn: Khôi theo xác nhận công khai; ngày xác nhận riêng chưa nêu, không lấy ngày đọc làm ngày xác nhận | sau: H2 5 | giữ nguyên hiện trạng–phương án–kết quả có giới hạn; hồ sơ Sheet chưa phản ánh, không đổi thành chưa xác minh. BT05 | Trực chốt phân tán/điều phối tập trung; 14 khu vực Ba Đình, Đống Đa, Hoàn Kiếm, Hai Bà Trưng, Cầu Giấy, Thanh Xuân, Tây Hồ, Hoàng Mai, Long Biên, Hà Đông, Thanh Trì, Gia Lâm, Hoài Đức, Đông Anh; xe 1–2 m³ bố trí trung tâm Đống Đa/Ba Đình/Hoàn Kiếm; xe 3–10 m³ theo Vành đai 2/3, hướng Hà Đông/Long Biên; tiếp nhận 24/7, tài xế gọi lại khoảng 3 phút, khung 15–30 phút có điều kiện và giấy phép ban ngày/đêm | trước: #dieu-phoi-ha-noi | nguồn: Khôi được ghi xác nhận thực tế, ngày riêng chưa nêu | sau: H2 4 | giữ đủ địa điểm, loại xe, điều kiện; không đổi thành chi nhánh pháp lý. BT06 | Bảo hành hút tối đa 12 tháng theo phiếu, hút sót/loại trừ nứt thấm, hẹn lịch 24h; hotline/Zalo 0943.789.121; 30 URL tra cứu và phân biệt vùng nhận việc với link | trước: #ho-tro-sau-thi-cong/#dia-ban/CTA | nguồn: live + chính sách công khai tháng 6/2026; không suy thêm ngày duyệt | sau: H2 7/8/CTA | giữ đầy đủ. BT07 | “4.9/5 - (7 bình chọn)” cuối bài là số bình chọn hiển thị; không thấy lời đánh giá khách có tên/nguồn trong nội dung chính | nguồn: quan sát trực tiếp 15/10 | giữ bản ghi, không biến thành 7 khách đã xác minh hay thêm rating schema. Nếu có đánh giá chủ máy duyệt ở nguồn khác, tiếp nhận và giữ đúng lời/nguồn/phạm vi. Bản đầu vào Sheet được lưu trong hồ sơ cục bộ sheet_review/HN-001-audit-2026-10-15/sheet-before.json; hồ sơ nghiên cứu chứa bản chép hiện trạng, heading và danh mục bảo vệ. Chưa có bản sau sửa vì nhiệm vụ chỉ brief. MA TRẬN NHU CẦU → VIỆC CẢI THIỆN: - Giá/tổng tiền | #1/#2/#4/#5 nhiều bảng; #3 bảng ảnh, phạm vi tính chưa đồng đều | HN-001 đã có bậc, tối thiểu, ví dụ và phụ phí | GIỮ số liệu, GỘP cụm giá, làm rõ khoản gồm/chưa gồm và thuế | H2 2, Đăng, đối chiếu bảng gốc và phép tính đúng. - Xác nhận m³/khoán | #2/#5 nói khách kiểm tra thông số nhưng ít minh chứng đo cụ thể; #1/#4 đơn vị bảng khó so; #3 không hướng dẫn đo | HN-001 có đầu/cuối và nước sục rửa | VIẾT SÂU cách nhiều lượt và bổ sung ảnh/phiếu khi có quyền | Khôi nguồn, Đăng viết, Tân tư liệu; H2 2/6, không cộng trùng, không dùng áp lực/dung tích xe. - Ngõ/tiếp cận | #1/#2/#4/#5 có xe/ống/phương pháp, một số lời hứa rộng; #3 thiếu thao tác chuẩn bị | HN-001 đã có ba loại công trình và ca 80 m | GIỮ khảo sát có điều kiện, thêm bảng thông tin gửi và phương án theo giới hạn thật | H2 3/4; nguồn vận hành, đạt khi không suy mọi ngõ làm được. - Kết quả/bảo hành | cả 5 có quy trình hoặc cam kết; #5 có case, hồ sơ đo không đi kèm; #3 có phiếu/nhưng tiêu chí ít chi tiết | HN-001 đã có mẫu phiếu/loại trừ | GIỮ và nối dữ kiện từng ca với phép kiểm tra, ghi nhánh còn lỗi | H2 5–7, Khôi/Đăng/Tân; ảnh phải khớp và phân biệt lượng với kết quả xả. - Sau thu gom | #1 có quy trình vận chuyển/xử lý, #4 FAQ có đề cập; #2/#3/#5 chưa cho hồ sơ xử lý gắn ca trong phần đọc | HN-001 chưa giải thích nơi nhận/chứng từ | THU THẬP nguồn rồi bổ sung ngắn theo phạm vi thật | H2 6; không biến nhận định đối thủ thành giấy phép của mình. - Địa bàn | các đối thủ có danh sách vùng/chi nhánh; Toàn Việt có 30 link và danh sách nhận việc có điều kiện | GIỮ hub hướng dẫn, không sao chép bảng phường quận và không gọi vùng phục vụ là chi nhánh | H2 8; Phường xã cũ là dữ liệu có mốc, không phải phạm vi dịch vụ tự động. ĐẦU VIỆC CỤ THỂ (người viết: Đăng; nguồn: Khôi; Tân làm tư liệu sau bàn giao; hạn chưa ấn định; chưa tự đổi trạng thái): P1-01 | Hồ sơ/J9/VH so với live: ba ca J9 là minh họa, slot chờ dữ liệu nhưng live có 3 ca khác, đo/phụ phí/điều phối ghi Khôi xác nhận. Lập bảng chênh lệch cho quản lý đối chiếu nguồn đã có và gắn mã gốc/quyền tư liệu. Không xóa/đổi J9, không hạ nhãn dữ kiện live, không tự sửa tab khác. Lý do: ngăn dùng nhầm ca và nghiệm thu sai. Đạt khi quản lý quyết định trên nguồn; chưa coi website sai vì Sheet cũ. P2-01 | Luồng đầu bài: phân loại hút/thông đang sau nhiều mục giá/case; ảnh hero chiếm phần lớn khung nhìn đầu. Đề xuất trả lời nhanh, link phân loại/giá/phạm vi và rút phần trình bày hero nếu được duyệt. Lý do: tìm câu trả lời/đặt dịch vụ nhanh; tác động chuyển đổi chưa đo. Đạt khi kiểm tra được trên desktop và mobile sau triển khai. P2-02 | 5 H2 liên tiếp về giá/khối lượng: gộp cụm ở N9, giữ bảng, phương pháp, phụ phí và ví dụ; FAQ dùng đáp ngắn dẫn neo. Lý do: giảm lặp giữa giá–tổng tiền–mẫu phiếu–FAQ. Không có lỗi câu hỏng rõ trong nội dung chính đã đọc; không quy lỗi plugin/tác giả hoặc sửa đại trà chỉ vì giống H2. P2-03 | #do-luong-thuc-te/#quy-trinh: bổ sung cách ghi xe nhiều lượt, cộng tổng, nước sục rửa và ảnh chỉ thị mức đầu/cuối trên cùng xe. Cần Khôi mô tả phương pháp thực tế và phiếu được công khai. Lý do: khách tự đối chiếu thay vì chỉ nghe cam kết; không lấy sức chứa bồn làm số m³. P2-04 | #phu-phi-ha-noi: giờ hành chính 7–18h và phí sau 22h đã có; khoảng 18–22h chưa giải thích, thuế và phí khảo sát chưa nêu rõ tại bài (trang giá ghi khảo sát miễn phí). Thu nguồn vận hành cho ngoại lệ, khoản đã gồm, nước sục rửa, VAT/chứng từ; giữ giá cũ trong lúc chờ, không suy không phí/thuế đã gồm. Đạt khi có câu trả lời và phạm vi áp dụng, khớp trang giá. P2-05 | Ca Trần Thái Tông: 4 m³ là lượng được công khai, cách mở nắp/rọi đèn mô tả kiểm tra tình trạng, chưa nói phương pháp đối chiếu số 4 m³. Bổ sung từ hồ sơ Khôi; giữ số đã xác nhận, không dùng quan sát hố ga thay đo thể tích. Đạt khi tách rõ phép xác nhận lượng và nghiệm thu kết quả. P2-06 | 3 ca/ảnh: lập liên kết tư liệu gốc và quyền dùng, phiếu che dữ liệu nếu có; Tân nhận mã ca/ảnh/đoạn cần chứng minh/vị trí đặt, bổ sung video khi đủ nguồn. Live đã có ba ảnh với chú thích, không giao như thể chưa có ảnh. Chưa thấy video nhúng, chưa kiểm chứng quyền dùng từ hồ sơ Sheet. Đạt khi ảnh khớp ca, không ảnh AI/công trình khác làm bằng chứng; thiếu tư liệu vẫn giữ phần hồ sơ mở. P2-07 | #quy-trinh: bổ sung phần sau thu gom từ hồ sơ vận hành, gồm bên vận chuyển/nơi tiếp nhận/chứng từ có thể công khai. Lý do: nhu cầu trách nhiệm sau thi công được đối thủ đề cập nhưng bài mình chưa trả lời. Chưa có nguồn thì chưa xuất bản lời khẳng định đạt chuẩn/giấy phép. P2-08 | #dia-ban và đối chiếu O9: giữ 30 link/địa điểm đã duyệt, bổ sung mô tả chọn Ba Đình/bể chung, Hoàn Kiếm/tiếp cận phố cổ, Tây Hồ/từng ngăn–tuyến; không chép lại case hoặc đổi địa danh. Đạt khi hub hướng dẫn chung, bài quận giữ giá trị riêng; đối chiếu mới chỉ 3 bài O9, không kết luận toàn bộ 93 URL hay cannibalization. P2-09 | Metadata và FAQ: title/meta hiện đúng chủ đề, không cần thay chỉ để “tối ưu”; dùng phương án N9 nếu duyệt hướng mới. FAQ schema sau biên tập phải khớp phần hiển thị; bảo toàn số liệu và điều kiện, không tạo đánh giá/rich result giả. Đạt bằng đọc lại live và kiểm tra riêng JSON, không chỉ nhìn editor. P3-01 | Đo lường: lấy GSC đúng URL, kỳ 28 ngày đầy đủ gần nhất và kỳ trước, Web; ghi bộ lọc quốc gia/thiết bị thực dùng, nhóm truy vấn giá/ngõ/hút hay thông/địa bàn. Sau sửa so kỳ đủ dữ liệu tương đương, không gộp trước/sau ngày sửa thành kết quả. Chưa có dữ liệu thì không gán số hoặc khẳng định tăng hạng. P3-02 | SERP bổ sung: chạy lại từ Hà Nội khi có điều kiện, lưu giờ/thiết bị/vị trí và Top 5 mới riêng; không thay thứ tự quan sát phiên IP Cần Thơ hoặc gọi đó là local rank Hà Nội. NGHIỆM THU: D01 đã có đọc toàn bài + metadata/heading + lỗi/khoảng trống + danh mục bảo toàn, technical chỉ phần quan sát. D02 đã quan sát/đọc 5/5 và 3 bài nội bộ, có nguồn/ma trận/brief; thiếu GSC/cuộc gọi được ghi rõ. Nghiệm thu triển khai vẫn cần nguồn hồ sơ tương ứng, bảo toàn trước/sau, tư liệu thật, URL public desktop/mobile và người có thẩm quyền; lần này không tick hoặc đổi trạng thái. | AC9: Chưa có3case xác minh; chờ Khôi bổ sung hồ sơ. Bổ sung 15/10/2026: 1. CHÊNH LỆCH HỒ SƠ, KHÔNG PHẢI KẾT LUẬN CA LIVE GIẢ: J9 có Chùa Bộc/Văn Quán nhà liền kề/Lạc Long Quân, đều nhãn minh họa; Hồ sơ case HN-001-C1/C2/C3 chờ Khôi, chưa mã gốc/tư liệu/xác nhận/quyền công khai. Live lại có Văn Chương/Trần Thái Tông/Văn Quán chung cư mini, ghi Khôi đã cung cấp và kiểm chứng, đã có 3 ảnh chú thích. Giữ nguyên J9 và các dữ kiện Khôi xác nhận; quản lý đối chiếu hồ sơ đã có, quyết định cập nhật các tab trong công việc riêng. Không dùng ba minh họa thay ca thật, không đánh dấu đủ ba hồ sơ trong Sheet. 2. VH-01…VH-15 vẫn chờ nguồn nhưng live đã ghi xác nhận Khôi cho đo lượng/phụ phí/điều phối, có khu vực bố trí xe và khung gọi lại 3 phút/15–30 phút có điều kiện. Cần dẫn nguồn xác nhận đã có vào hồ sơ quản lý; không bắt xác minh lại hoặc gỡ lời đã duyệt chỉ vì thiếu bản sao. Ngày xác nhận riêng chưa ghi, không tự lấy 15/10 làm ngày xác nhận. 3. Phần mới/chưa nêu đủ để viết sâu: phương pháp ghi từng lượt/nước sục rửa, phương pháp xác nhận 4 m³ ca Trần Thái Tông, áp dụng phụ phí 18–22h, thuế/khoản gồm/chưa gồm, hồ sơ vận chuyển–tiếp nhận chất thải. Khôi hoặc vận hành cung cấp; chỉ ảnh hưởng mục phụ thuộc, không chặn brief phần có nguồn. Bảng giá 04/09/2026 và bảo hành hiện đã đối chiếu khớp trang gốc, không tạo vướng mắc giá/bảo hành mới. 4. Ảnh ca đang hiển thị nhưng nguồn gốc/quyền công khai và phiếu che dữ liệu chưa có trong những tab đã đọc; chưa thấy video nhúng trong article. Cần liên kết tư liệu gốc để Tân nhận đúng ca và nghiệm thu media, không suy ảnh hỏng từ lazy-load, không tự thay ảnh đã duyệt. 5. GSC Wizard báo payment_required (hết trial/không có gói); chưa đọc được property/dữ liệu. Chưa tiếp cận cuộc gọi/tin nhắn Hà Nội. Không có volume/clicks/CTR để dùng; không suy doanh nghiệp không có quyền GSC. Cần người có quyền cung cấp báo cáo đúng URL/kỳ/bộ lọc nếu muốn nghiệm thu theo hiệu quả SEO. 6. Top 5 đã đọc đủ trong bối cảnh Google IP Cần Thơ; chưa có quan sát vị trí Hà Nội. Đây là giới hạn phạm vi, không phải thiếu đọc 5 trang. HTTP header/index GSC, QA toàn trang desktop/mobile, tốc độ và click CTA chưa được xác minh; không đánh dấu QA đạt. Đối chiếu nội bộ giới hạn 3 URL ở O9 và hai trang chính sách, chưa audit toàn bộ 93 URL. 7. Chưa có người nghiệm thu/hạn trong dòng đầu vào; không tự ấn định. Không yêu cầu quyền sửa WordPress vì lần này chỉ nghiên cứu/brief. | AD9: Chưa xác định | AE9: 15/10/2026 — URL HN-001 thực tế đã đọc toàn bộ nội dung chính bằng trình duyệt: https://dichvuhuthamcau.vn/hut-be-phot-tai-ha-noi/ Đọc từ mở bài đến CTA/FAQ, kiểm kê title/meta/H1/H2/H3, bảng, ca/ảnh/điều phối, link và JSON-LD. Công cụ web mở URL lỗi nhưng trình duyệt đọc thành công; không dùng lỗi công cụ để kết luận website lỗi. 5 organic đã quan sát đúng thứ tự cho “hút bể phốt Hà Nội”, cùng ngày (bối cảnh L9): 1. https://thongtacconghanoi.net/hut-be-phot-gia-re-2/ — đọc đủ nội dung chính + FAQ. 2. https://moitruongminhtam.vn/hut-be-phot-tai-ha-noi-2639.html — đọc đủ nội dung chính. 3. https://thanglongenvico.com/hut-be-phot-ha-noi/ — đọc đủ nội dung chính; xem ảnh bảng giá nhúng: https://thanglongenvico.com/hut-be-phot-ha-noi/wp-content/uploads/2024/12/bang-gia-hut-ham-cau-530x1024-2.png 4. https://kienmoitruong.com/ — đọc đủ nội dung chính + FAQ. 5. https://kienvesinh.com/ — đọc đủ nội dung chính, case + FAQ; trình duyệt đọc thành công dù công cụ web lỗi. Nội bộ O9, cùng ngày, đọc đủ nội dung chính: https://dichvuhuthamcau.vn/hut-be-phot-tai-ba-dinh/ https://dichvuhuthamcau.vn/hut-be-phot-tai-hoan-kiem/ https://dichvuhuthamcau.vn/hut-be-phot-tai-tay-ho/ Nguồn hỗ trợ đã đọc cùng ngày: https://dichvuhuthamcau.vn/bang-gia/ — đọc phần giá hút, điều kiện áp dụng, bảo hành và FAQ đang mở; không khẳng định đã mở mọi accordion. https://dichvuhuthamcau.vn/chinh-sach-bao-hanh/ — đọc nội dung chính. https://dichvuhuthamcau.vn/robots.txt — đọc văn bản quy tắc. Không đưa các URL khác trong 30 link điều hướng vào danh sách đã đọc. Ngày đọc không phải ngày doanh nghiệp xác nhận. Đây là kiểm tra trước lập brief; không có sửa website trong phiên. | AF9: =IF(AND(A9=TRUE,Y9="Đủ bước, chờ nghiệm thu"),1,0) -> 0
